Workbook

Sheet Raw_Data
A1: FinSight — Raw Transaction Sample (synthetic)
A3: transaction_id | B3: customer_id | C3: transaction_date | D3: month | E3: category | F3: merchant_name | G3: transaction_amount | H3: is_campaign_transaction | I3: income_band | J3: rfm_segment | K3: city
A4: T00010399 | B4: C01478 | C4: 2025-08-03 | D4: 2025-08 | E4: Entertainment | F4: Entertainment Medium #056 | G4: 2336.76 | H4: 0 | I4: High | J4: High Value | K4: Jaipur
A5: T00013726 | B5: C01288 | C5: 2025-08-04 | D5: 2025-08 | E5: Dining | F5: Dining Medium #005 | G5: 1146.53 | H5: 0 | I5: Lower-Mid | J5: Regular | K5: Kolkata
A6: T00012719 | B6: C00887 | C6: 2025-08-05 | D6: 2025-08 | E6: Dining | F6: Dining Small #043 | G6: 1018.65 | H6: 0 | I6: Lower-Mid | J6: High Value | K6: Bengaluru
A7: T00018888 | B7: C00958 | C7: 2025-08-06 | D7: 2025-08 | E7: Dining | F7: Dining Medium #038 | G7: 809.93 | H7: 0 | I7: Mid | J7: High Value | K7: Kochi
A8: T00015877 | B8: C01422 | C8: 2025-08-08 | D8: 2025-08 | E8: Entertainment | F8: Entertainment Medium #056 | G8: 1818.69 | H8: 0 | I8: Mid | J8: High Value | K8: Hyderabad
A9: T00003925 | B9: C01284 | C9: 2025-08-09 | D9: 2025-08 | E9: Dining | F9: Dining Small #043 | G9: 2424.37 | H9: 0 | I9: Mid | J9: High Value | K9: Chennai
A10: T00004773 | B10: C00754 | C10: 2025-08-12 | D10: 2025-08 | E10: Dining | F10: Dining Medium #005 | G10: 1145.77 | H10: 0 | I10: Mid | J10: High Value | K10: Ahmedabad
A11: T00017232 | B11: C00642 | C11: 2025-08-13 | D11: 2025-08 | E11: Fuel | F11: Dining Small #004 | G11: 2247.61 | H11: 0 | I11: Upper-Mid | J11: High Value | K11: Ahmedabad
A12: T00016356 | B12: C00919 | C12: 2025-08-15 | D12: 2025-08 | E12: Fuel | F12: Fuel Medium #015 | G12: 1742.64 | H12: 1 | I12: Lower-Mid | J12: High Value | K12: Chennai
A13: T00003979 | B13: C00428 | C13: 2025-08-16 | D13: 2025-08 | E13: Fuel | F13: Dining Small #004 | G13: 1238.14 | H13: 0 | I13: Upper-Mid | J13: Regular | K13: Bengaluru
A14: T00004374 | B14: C00377 | C14: 2025-08-16 | D14: 2025-08 | E14: Shopping | F14: Shopping Small #040 | G14: 4182.67 | H14: 0 | I14: High | J14: High Value | K14: Ahmedabad
A15: T00014245 | B15: C01216 | C15: 2025-08-17 | D15: 2025-08 | E15: Electronics | F15: Electronics Small #039 | G15: 1342.76 | H15: 0 | I15: Mid | J15: High Value | K15: Kochi
... A503: T00018231 | B503: C01423 | C503: 2026-07-31 | D503: 2026-07 | E503: Electronics | F503: Travel Medium #027 | G503: 910.04 | H503: 0 | I503: Mid | J503: Regular | K503: Delhi

Sheet Pivot_Analysis
A1: Revenue by Category x Month (SUMIFS over Raw_Data — pivot-style)
A3: Category | B3: 2025-08 | C3: 2025-09 | D3: 2025-10 | E3: 2025-11 | F3: 2025-12 | G3: 2026-01 | H3: 2026-02 | I3: 2026-03 | J3: 2026-04 | K3: 2026-05 | L3: 2026-06 | M3: 2026-07 | N3: Total
A4: Dining | B4: =SUMIFS(Raw_Data!$G$4:$G$503,Raw_Data!$E$4:$E$503,$A4,Raw_Data!$D$4:$D$503,B$3) | C4: =SUMIFS(Raw_Data!$G$4:$G$503,Raw_Data!$E$4:$E$503,$A4,Raw_Data!$D$4:$D$503,C$3) | D4: =SUMIFS(Raw_Data!$G$4:$G$503,Raw_Data!$E$4:$E$503,$A4,Raw_Data!$D$4:$D$503,D$3) | E4: =SUMIFS(Raw_Data!$G$4:$G$503,Raw_Data!$E$4:$E$503,$A4,Raw_Data!$D$4:$D$503,E$3) | F4: =SUMIFS(Raw_Data!$G$4:$G$503,Raw_Data!$E$4:$E$503,$A4,Raw_Data!$D$4:$D$503,F$3) | G4: =SUMIFS(Raw_Data!$G$4:$G$503,Raw_Data!$E$4:$E$503,$A4,Raw_Data!$D$4:$D$503,G$3) | H4: =SUMIFS(Raw_Data!$G$4:$G$503,Raw_Data!$E$4:$E$503,$A4,Raw_Data!$D$4:$D$503,H$3) | I4: =SUMIFS(Raw_Data!$G$4:$G$503,Raw_Data!$E$4:$E$503,$A4,Raw_Data!$D$4:$D$503,I$3) | ... M4: =SUMIFS(Raw_Data!$G$4:$G$503,Raw_Data!$E$4:$E$503,$A4,Raw_Data!$D$4:$D$503,M$3) | N4: =SUM(B4:M4)
A5: Electronics | B5: =SUMIFS(Raw_Data!$G$4:$G$503,Raw_Data!$E$4:$E$503,$A5,Raw_Data!$D$4:$D$503,B$3) | C5: =SUMIFS(Raw_Data!$G$4:$G$503,Raw_Data!$E$4:$E$503,$A5,Raw_Data!$D$4:$D$503,C$3) | D5: =SUMIFS(Raw_Data!$G$4:$G$503,Raw_Data!$E$4:$E$503,$A5,Raw_Data!$D$4:$D$503,D$3) | E5: =SUMIFS(Raw_Data!$G$4:$G$503,Raw_Data!$E$4:$E$503,$A5,Raw_Data!$D$4:$D$503,E$3) | F5: =SUMIFS(Raw_Data!$G$4:$G$503,Raw_Data!$E$4:$E$503,$A5,Raw_Data!$D$4:$D$503,F$3) | G5: =SUMIFS(Raw_Data!$G$4:$G$503,Raw_Data!$E$4:$E$503,$A5,Raw_Data!$D$4:$D$503,G$3) | H5: =SUMIFS(Raw_Data!$G$4:$G$503,Raw_Data!$E$4:$E$503,$A5,Raw_Data!$D$4:$D$503,H$3) | I5: =SUMIFS(Raw_Data!$G$4:$G$503,Raw_Data!$E$4:$E$503,$A5,Raw_Data!$D$4:$D$503,I$3) | ... M5: =SUMIFS(Raw_Data!$G$4:$G$503,Raw_Data!$E$4:$E$503,$A5,Raw_Data!$D$4:$D$503,M$3) | N5: =SUM(B5:M5)
A6: Entertainment | B6: =SUMIFS(Raw_Data!$G$4:$G$503,Raw_Data!$E$4:$E$503,$A6,Raw_Data!$D$4:$D$503,B$3) | C6: =SUMIFS(Raw_Data!$G$4:$G$503,Raw_Data!$E$4:$E$503,$A6,Raw_Data!$D$4:$D$503,C$3) | D6: =SUMIFS(Raw_Data!$G$4:$G$503,Raw_Data!$E$4:$E$503,$A6,Raw_Data!$D$4:$D$503,D$3) | E6: =SUMIFS(Raw_Data!$G$4:$G$503,Raw_Data!$E$4:$E$503,$A6,Raw_Data!$D$4:$D$503,E$3) | F6: =SUMIFS(Raw_Data!$G$4:$G$503,Raw_Data!$E$4:$E$503,$A6,Raw_Data!$D$4:$D$503,F$3) | G6: =SUMIFS(Raw_Data!$G$4:$G$503,Raw_Data!$E$4:$E$503,$A6,Raw_Data!$D$4:$D$503,G$3) | H6: =SUMIFS(Raw_Data!$G$4:$G$503,Raw_Data!$E$4:$E$503,$A6,Raw_Data!$D$4:$D$503,H$3) | I6: =SUMIFS(Raw_Data!$G$4:$G$503,Raw_Data!$E$4:$E$503,$A6,Raw_Data!$D$4:$D$503,I$3) | ... M6: =SUMIFS(Raw_Data!$G$4:$G$503,Raw_Data!$E$4:$E$503,$A6,Raw_Data!$D$4:$D$503,M$3) | N6: =SUM(B6:M6)
A7: Fuel | B7: =SUMIFS(Raw_Data!$G$4:$G$503,Raw_Data!$E$4:$E$503,$A7,Raw_Data!$D$4:$D$503,B$3) | C7: =SUMIFS(Raw_Data!$G$4:$G$503,Raw_Data!$E$4:$E$503,$A7,Raw_Data!$D$4:$D$503,C$3) | D7: =SUMIFS(Raw_Data!$G$4:$G$503,Raw_Data!$E$4:$E$503,$A7,Raw_Data!$D$4:$D$503,D$3) | E7: =SUMIFS(Raw_Data!$G$4:$G$503,Raw_Data!$E$4:$E$503,$A7,Raw_Data!$D$4:$D$503,E$3) | F7: =SUMIFS(Raw_Data!$G$4:$G$503,Raw_Data!$E$4:$E$503,$A7,Raw_Data!$D$4:$D$503,F$3) | G7: =SUMIFS(Raw_Data!$G$4:$G$503,Raw_Data!$E$4:$E$503,$A7,Raw_Data!$D$4:$D$503,G$3) | H7: =SUMIFS(Raw_Data!$G$4:$G$503,Raw_Data!$E$4:$E$503,$A7,Raw_Data!$D$4:$D$503,H$3) | I7: =SUMIFS(Raw_Data!$G$4:$G$503,Raw_Data!$E$4:$E$503,$A7,Raw_Data!$D$4:$D$503,I$3) | ... M7: =SUMIFS(Raw_Data!$G$4:$G$503,Raw_Data!$E$4:$E$503,$A7,Raw_Data!$D$4:$D$503,M$3) | N7: =SUM(B7:M7)
A8: Grocery | B8: =SUMIFS(Raw_Data!$G$4:$G$503,Raw_Data!$E$4:$E$503,$A8,Raw_Data!$D$4:$D$503,B$3) | C8: =SUMIFS(Raw_Data!$G$4:$G$503,Raw_Data!$E$4:$E$503,$A8,Raw_Data!$D$4:$D$503,C$3) | D8: =SUMIFS(Raw_Data!$G$4:$G$503,Raw_Data!$E$4:$E$503,$A8,Raw_Data!$D$4:$D$503,D$3) | E8: =SUMIFS(Raw_Data!$G$4:$G$503,Raw_Data!$E$4:$E$503,$A8,Raw_Data!$D$4:$D$503,E$3) | F8: =SUMIFS(Raw_Data!$G$4:$G$503,Raw_Data!$E$4:$E$503,$A8,Raw_Data!$D$4:$D$503,F$3) | G8: =SUMIFS(Raw_Data!$G$4:$G$503,Raw_Data!$E$4:$E$503,$A8,Raw_Data!$D$4:$D$503,G$3) | H8: =SUMIFS(Raw_Data!$G$4:$G$503,Raw_Data!$E$4:$E$503,$A8,Raw_Data!$D$4:$D$503,H$3) | I8: =SUMIFS(Raw_Data!$G$4:$G$503,Raw_Data!$E$4:$E$503,$A8,Raw_Data!$D$4:$D$503,I$3) | ... M8: =SUMIFS(Raw_Data!$G$4:$G$503,Raw_Data!$E$4:$E$503,$A8,Raw_Data!$D$4:$D$503,M$3) | N8: =SUM(B8:M8)
A9: Healthcare | B9: =SUMIFS(Raw_Data!$G$4:$G$503,Raw_Data!$E$4:$E$503,$A9,Raw_Data!$D$4:$D$503,B$3) | C9: =SUMIFS(Raw_Data!$G$4:$G$503,Raw_Data!$E$4:$E$503,$A9,Raw_Data!$D$4:$D$503,C$3) | D9: =SUMIFS(Raw_Data!$G$4:$G$503,Raw_Data!$E$4:$E$503,$A9,Raw_Data!$D$4:$D$503,D$3) | E9: =SUMIFS(Raw_Data!$G$4:$G$503,Raw_Data!$E$4:$E$503,$A9,Raw_Data!$D$4:$D$503,E$3) | F9: =SUMIFS(Raw_Data!$G$4:$G$503,Raw_Data!$E$4:$E$503,$A9,Raw_Data!$D$4:$D$503,F$3) | G9: =SUMIFS(Raw_Data!$G$4:$G$503,Raw_Data!$E$4:$E$503,$A9,Raw_Data!$D$4:$D$503,G$3) | H9: =SUMIFS(Raw_Data!$G$4:$G$503,Raw_Data!$E$4:$E$503,$A9,Raw_Data!$D$4:$D$503,H$3) | I9: =SUMIFS(Raw_Data!$G$4:$G$503,Raw_Data!$E$4:$E$503,$A9,Raw_Data!$D$4:$D$503,I$3) | ... M9: =SUMIFS(Raw_Data!$G$4:$G$503,Raw_Data!$E$4:$E$503,$A9,Raw_Data!$D$4:$D$503,M$3) | N9: =SUM(B9:M9)
A10: Lifestyle | B10: =SUMIFS(Raw_Data!$G$4:$G$503,Raw_Data!$E$4:$E$503,$A10,Raw_Data!$D$4:$D$503,B$3) | C10: =SUMIFS(Raw_Data!$G$4:$G$503,Raw_Data!$E$4:$E$503,$A10,Raw_Data!$D$4:$D$503,C$3) | D10: =SUMIFS(Raw_Data!$G$4:$G$503,Raw_Data!$E$4:$E$503,$A10,Raw_Data!$D$4:$D$503,D$3) | E10: =SUMIFS(Raw_Data!$G$4:$G$503,Raw_Data!$E$4:$E$503,$A10,Raw_Data!$D$4:$D$503,E$3) | F10: =SUMIFS(Raw_Data!$G$4:$G$503,Raw_Data!$E$4:$E$503,$A10,Raw_Data!$D$4:$D$503,F$3) | G10: =SUMIFS(Raw_Data!$G$4:$G$503,Raw_Data!$E$4:$E$503,$A10,Raw_Data!$D$4:$D$503,G$3) | H10: =SUMIFS(Raw_Data!$G$4:$G$503,Raw_Data!$E$4:$E$503,$A10,Raw_Data!$D$4:$D$503,H$3) | I10: =SUMIFS(Raw_Data!$G$4:$G$503,Raw_Data!$E$4:$E$503,$A10,Raw_Data!$D$4:$D$503,I$3) | ... M10: =SUMIFS(Raw_Data!$G$4:$G$503,Raw_Data!$E$4:$E$503,$A10,Raw_Data!$D$4:$D$503,M$3) | N10: =SUM(B10:M10)
A11: Shopping | B11: =SUMIFS(Raw_Data!$G$4:$G$503,Raw_Data!$E$4:$E$503,$A11,Raw_Data!$D$4:$D$503,B$3) | C11: =SUMIFS(Raw_Data!$G$4:$G$503,Raw_Data!$E$4:$E$503,$A11,Raw_Data!$D$4:$D$503,C$3) | D11: =SUMIFS(Raw_Data!$G$4:$G$503,Raw_Data!$E$4:$E$503,$A11,Raw_Data!$D$4:$D$503,D$3) | E11: =SUMIFS(Raw_Data!$G$4:$G$503,Raw_Data!$E$4:$E$503,$A11,Raw_Data!$D$4:$D$503,E$3) | F11: =SUMIFS(Raw_Data!$G$4:$G$503,Raw_Data!$E$4:$E$503,$A11,Raw_Data!$D$4:$D$503,F$3) | G11: =SUMIFS(Raw_Data!$G$4:$G$503,Raw_Data!$E$4:$E$503,$A11,Raw_Data!$D$4:$D$503,G$3) | H11: =SUMIFS(Raw_Data!$G$4:$G$503,Raw_Data!$E$4:$E$503,$A11,Raw_Data!$D$4:$D$503,H$3) | I11: =SUMIFS(Raw_Data!$G$4:$G$503,Raw_Data!$E$4:$E$503,$A11,Raw_Data!$D$4:$D$503,I$3) | ... M11: =SUMIFS(Raw_Data!$G$4:$G$503,Raw_Data!$E$4:$E$503,$A11,Raw_Data!$D$4:$D$503,M$3) | N11: =SUM(B11:M11)
A12: Travel | B12: =SUMIFS(Raw_Data!$G$4:$G$503,Raw_Data!$E$4:$E$503,$A12,Raw_Data!$D$4:$D$503,B$3) | C12: =SUMIFS(Raw_Data!$G$4:$G$503,Raw_Data!$E$4:$E$503,$A12,Raw_Data!$D$4:$D$503,C$3) | D12: =SUMIFS(Raw_Data!$G$4:$G$503,Raw_Data!$E$4:$E$503,$A12,Raw_Data!$D$4:$D$503,D$3) | E12: =SUMIFS(Raw_Data!$G$4:$G$503,Raw_Data!$E$4:$E$503,$A12,Raw_Data!$D$4:$D$503,E$3) | F12: =SUMIFS(Raw_Data!$G$4:$G$503,Raw_Data!$E$4:$E$503,$A12,Raw_Data!$D$4:$D$503,F$3) | G12: =SUMIFS(Raw_Data!$G$4:$G$503,Raw_Data!$E$4:$E$503,$A12,Raw_Data!$D$4:$D$503,G$3) | H12: =SUMIFS(Raw_Data!$G$4:$G$503,Raw_Data!$E$4:$E$503,$A12,Raw_Data!$D$4:$D$503,H$3) | I12: =SUMIFS(Raw_Data!$G$4:$G$503,Raw_Data!$E$4:$E$503,$A12,Raw_Data!$D$4:$D$503,I$3) | ... M12: =SUMIFS(Raw_Data!$G$4:$G$503,Raw_Data!$E$4:$E$503,$A12,Raw_Data!$D$4:$D$503,M$3) | N12: =SUM(B12:M12)

Sheet Campaign_Analysis
A1: Campaign Performance
A3: campaign_id | B3: campaign_name | C3: campaign_category | D3: channel | E3: engaged | F3: redeemed | G3: redemption_rate | H3: campaign_revenue | I3: discount_cost | J3: roi
A4: CMP017 | B4: Electronics Percentage Offer | C4: Electronics | D4: App | E4: 75 | F4: 65 | G4: 0.8667 | H4: 175557.12 | I4: 8777.85 | J4: 2
A5: CMP009 | B5: Shopping Percentage Offer | C5: Shopping | D5: Call | E5: 82 | F5: 66 | G5: 0.8049 | H5: 127620.22 | I5: 14038.24 | J5: 0.3636
A6: CMP027 | B6: Grocery Cashback Offer | C6: Grocery | D6: App | E6: 60 | F6: 55 | G6: 0.9167 | H6: 119416.61 | I6: 24000 | J6: -0.2536
A7: CMP018 | B7: Fuel Percentage Offer | C7: Fuel | D7: Web | E7: 69 | F7: 32 | G7: 0.4638 | H7: 113260.05 | I7: 22652 | J7: -0.25
A8: CMP003 | B8: Lifestyle Flat Offer | C8: Lifestyle | D8: Web | E8: 66 | F8: 60 | G8: 0.9091 | H8: 104191 | I8: 8100 | J8: 0.9295
A9: CMP014 | B9: Travel Flat Offer | C9: Travel | D9: App | E9: 77 | F9: 39 | G9: 0.5065 | H9: 95918.37 | I9: 8250 | J9: 0.744
A10: CMP001 | B10: Fuel Cashback Offer | C10: Fuel | D10: Web | E10: 74 | F10: 64 | G10: 0.8649 | H10: 88932.16 | I10: 8100 | J10: 0.6469
A11: CMP012 | B11: Travel Percentage Offer | C11: Travel | D11: Call | E11: 76 | F11: 35 | G11: 0.4605 | H11: 87477.4 | I11: 23618.91 | J11: -0.4444
A12: CMP023 | B12: Dining Cashback Offer | C12: Dining | D12: Web | E12: 70 | F12: 61 | G12: 0.8714 | H12: 77292.59 | I12: 14400 | J12: -0.1949
A13: CMP020 | B13: Shopping Percentage Offer | C13: Shopping | D13: Web | E13: 75 | F13: 36 | G13: 0.48 | H13: 71867.82 | I13: 13654.88 | J13: -0.2105
A14: CMP013 | B14: Electronics Percentage Offer | C14: Electronics | D14: Branch | E14: 75 | F14: 39 | G14: 0.52 | H14: 70430.94 | I14: 10564.62 | J14: 0
A15: CMP021 | B15: Grocery Percentage Offer | C15: Grocery | D15: App | E15: 75 | F15: 39 | G15: 0.52 | H15: 70037.59 | I15: 6303.4 | J15: 0.6667
... A33: CMP024 | B33: Fuel Percentage Offer | C33: Fuel | D33: Call | E33: 77 | F33: 16 | G33: 0.2078 | H33: 9720.72 | I33: 2041.35 | J33: -0.2857

Sheet Customer_Analysis
A1: Customer Segment Analysis (SUMIFS / COUNTIFS)
A3: RFM Segment | B3: Transactions (COUNTIFS) | C3: Revenue (SUMIFS) | D3: Campaign Txns (COUNTIFS)
A4: At Risk | B4: =COUNTIFS(Raw_Data!$J$4:$J$503,$A4) | C4: =SUMIFS(Raw_Data!$G$4:$G$503,Raw_Data!$J$4:$J$503,$A4) | D4: =COUNTIFS(Raw_Data!$J$4:$J$503,$A4,Raw_Data!$H$4:$H$503,1)
A5: High Value | B5: =COUNTIFS(Raw_Data!$J$4:$J$503,$A5) | C5: =SUMIFS(Raw_Data!$G$4:$G$503,Raw_Data!$J$4:$J$503,$A5) | D5: =COUNTIFS(Raw_Data!$J$4:$J$503,$A5,Raw_Data!$H$4:$H$503,1)
A6: Low Engagement | B6: =COUNTIFS(Raw_Data!$J$4:$J$503,$A6) | C6: =SUMIFS(Raw_Data!$G$4:$G$503,Raw_Data!$J$4:$J$503,$A6) | D6: =COUNTIFS(Raw_Data!$J$4:$J$503,$A6,Raw_Data!$H$4:$H$503,1)
A7: Regular | B7: =COUNTIFS(Raw_Data!$J$4:$J$503,$A7) | C7: =SUMIFS(Raw_Data!$G$4:$G$503,Raw_Data!$J$4:$J$503,$A7) | D7: =COUNTIFS(Raw_Data!$J$4:$J$503,$A7,Raw_Data!$H$4:$H$503,1)
A9: XLOOKUP demo — income band for a customer id:
A10: Customer ID | B10: C00001
A11: Income band | B11: =XLOOKUP(B10,dim_customers!$A$2:$A$1501,dim_customers!$B$2:$B$1501,"Not found")

Sheet Summary
A1: FinSight — Summary (synthetic data)
A3: Total sample transactions | B3: =COUNTA(Raw_Data!$E$4:$E$503)
A4: Total sample revenue | B4: =SUM(Raw_Data!$G$4:$G$503)
A5: Campaign transactions (sample) | B5: =COUNTIFS(Raw_Data!$H$4:$H$503,1)
A6: Avg transaction value (sample) | B6: =AVERAGE(Raw_Data!$G$4:$G$503)
A9: Note: figures on this sheet summarise the 500-row Raw_Data sample, not the full dataset. All data is synthetic.

Sheet dim_customers
A1: customer_id | B1: income_band | C1: rfm_segment
A2: C00001 | B2: Upper-Mid | C2: Regular
A3: C00002 | B3: Mid | C3: Low Engagement
A4: C00003 | B4: Upper-Mid | C4: Regular
A5: C00004 | B5: Mid | C5: Low Engagement
A6: C00005 | B6: Low | C6: Low Engagement
A7: C00006 | B7: High | C7: At Risk
A8: C00007 | B8: Upper-Mid | C8: Regular
A9: C00008 | B9: Upper-Mid | C9: Low Engagement
A10: C00009 | B10: Low | C10: At Risk
A11: C00010 | B11: Mid | C11: Low Engagement
A12: C00011 | B12: Lower-Mid | C12: Low Engagement
... A79: C00078 | B79: Mid | C79: High Value
A80: C00079 | B80: Mid
A81: C00080 | B81: Upper-Mid | C81: Regular
A82: C00081 | B82: Mid | C82: High Value
A83: C00082 | B83: Lower-Mid | C83: Regular
A84: C00083 | B84: Upper-Mid | C84: Regular
A85: C00084 | B85: Low | C85: Low Engagement
A86: C00085 | B86: Low | C86: Low Engagement
A87: C00086 | B87: Low | C87: Low Engagement
A88: C00087 | B88: Upper-Mid | C88: At Risk
A89: C00088 | B89: Mid | C89: High Value
A90: C00089 | B90: Low | C90: Regular
A91: C00090 | B91: Mid | C91: High Value
A92: C00091 | B92: Low | C92: Regular
... A112: C00111 | B112: Mid | C112: High Value
A113: C00112 | B113: Lower-Mid
A114: C00113 | B114: Lower-Mid | C114: Regular
A115: C00114 | B115: Mid | C115: High Value
A116: C00115 | B116: Low | C116: High Value
A117: C00116 | B117: Upper-Mid | C117: High Value
A118: C00117 | B118: Upper-Mid | C118: Low Engagement
A119: C00118 | B119: Mid | C119: High Value
A120: C00119 | B120: Mid | C120: High Value
A121: C00120 | B121: Mid | C121: High Value
A122: C00121 | B122: Mid | C122: High Value
A123: C00122 | B123: Mid | C123: Low Engagement
A124: C00123 | B124: Low | C124: Low Engagement
A125: C00124 | B125: Lower-Mid
...
